<?xml version="1.0"?>
<robot name="barbot_test">

<!-- LINKS -->
  <link name="world">
  </link>

<!-- from stl's -->

  <!-- <link name="link1"> -->
  <!--   <visual> -->
  <!--     <origin rpy="0.0 0 0" xyz="0 0 0" /> -->
  <!--     <geometry> -->
  <!--       <mesh filename="package://bar-bot/mesh/Link0.STL" scale="0.001 0.001 0.001"/> -->
  <!--     </geometry> -->
  <!--   </visual> -->
  <!-- </link> -->
  <!-- <link name="link2"> -->
  <!--   <visual> -->
  <!--     <origin rpy="0.0 0 0" xyz="0 0 0"/> -->
  <!--     <geometry> -->
  <!--       <mesh filename="package://bar-bot/mesh/Link1.STL" scale="0.001 0.001 0.001"/> -->
  <!--     </geometry> -->
  <!--   </visual> -->
  <!-- </link> -->
  <link name="link3">
    <visual>
      <origin rpy="0.0 0 0" xyz="0 0 0"/>
      <geometry>
        <mesh filename="package://bar-bot/mesh/Link2.STL" scale="0.001 0.001 0.001"/>
      </geometry>
    </visual>
  </link>
  <link name="link4">
    <visual>
      <origin rpy="0.0 0 0" xyz="0 0 0"/>
      <geometry>
        <mesh filename="package://bar-bot/mesh/Link3.STL" scale="0.001 0.001 0.001"/>
      </geometry>
    </visual>
  </link>
  <!-- <link name="link5"> -->
  <!--   <visual> -->
  <!--     <origin rpy="0.0 0 0" xyz="0 0 0"/> -->
  <!--     <geometry> -->
  <!--       <mesh filename="package://bar-bot/mesh/Link4_5.STL" scale="0.001 0.001 0.001"/> -->
  <!--     </geometry> -->
  <!--   </visual> -->
  <!-- </link> -->
  <!-- <link name="link6"> -->
  <!--   <visual> -->
  <!--     <origin rpy="0.0 0 0" xyz="0 0 0"/> -->
  <!--     <geometry> -->
  <!--       <mesh filename="package://bar-bot/mesh/Link4_5.STL" scale="0.001 0.001 0.001"/> -->
  <!--     </geometry> -->
  <!--   </visual> -->
  <!-- </link> -->

<!-- JOINTS -->
  <joint name="world_joint" type="fixed">
    <parent link="world"/>
    <child link="link3"/>
    <origin xyz ="0 0 0" rpy="0 0 0" />
    <axis xyz="0 0 1" />
  </joint>

  <!-- <joint name="joint1" type="continuous"> -->
  <!--   <child link="link2"/> -->
  <!--   <origin xyz ="0 0 0.0311" rpy="0 0 0" /> -->
  <!--   <axis xyz="0 0 1" /> -->
  <!-- </joint> -->

  <!-- <joint name="joint2" type="continuous"> -->
  <!--   <child link="link3"/> -->
  <!--   <origin xyz ="0.0611 0 0.050" rpy="0 -1.570796 -0.78539816" /> -->
  <!--   <axis xyz="0 1 0" /> -->
  <!-- </joint> -->

  <joint name="joint3" type="continuous">
    <parent link="link3"/>
    <child link="link4"/>
    <origin xyz ="0.15556 0 -0.0311" rpy="3.1415926 0 -1.570796" />
    <axis xyz="0 0 1" />
  </joint>

  <!-- <joint name="joint4" type="continuous"> -->
  <!--   <parent link="link4"/> -->
  <!--   <child link="link5"/> -->
  <!--   <origin xyz ="0.14142 0 -0.0311" rpy="3.1415926 0 -0.78539816" /> -->
  <!--   <axis xyz="0 0 1" /> -->
  <!-- </joint> -->

  <!-- GRIPPER -->
  <!-- <joint name="joint5" type="revolute"> -->
  <!-- <joint name="joint5" type="continuous"> -->
  <!--   <parent link="link5"/> -->
  <!--   <child link="link6"/> -->
  <!--   <origin xyz ="0.0811 0 0" rpy="0 0 0" /> -->
  <!--   <axis xyz="1 0 0" /> -->
  <!-- </joint> -->

</robot>

